<robot name = "robot">
    <link name="Body">
        <inertial>
            <origin xyz="0 0 3.978953015035716" rpy="0 0 0"/>
            <mass value="1" />
            <inertia ixx="100" ixy="0" ixz="0" iyy="100" iyz="0" izz="100" />
        </inertial>
        <visual>
            <origin xyz="0 0 3.978953015035716" rpy="0 0 0"/>
            <geometry>
                <box size="3.2555444803632065 2.742800704977322 1.1086016494912574" />
            </geometry>
            <material name="Cyan">
                <color rgba="0 1.0 1.0 1.0"/>
            </material>
        </visual>
        <collision>
            <origin xyz="0 0 3.978953015035716" rpy="0 0 0"/>
            <geometry>
                <box size="3.2555444803632065 2.742800704977322 1.1086016494912574" />
            </geometry>
        </collision>
    </link>
    <joint name="Body_Leg1" type="revolute">
       <parent link="Body"/>
       <child  link="Leg1"/>
       <origin rpy="0 0 0" xyz="-1.6277722401816033 -1.371400352488661 3.4246521902900873" />
       <axis xyz="0 1 0"/>
       <limit effort="0.0" lower="-3.14159" upper="3.14159" velocity="0.0"/>
    </joint>
    <link name="Leg1">
        <inertial>
            <origin xyz="-0.7851104569991724 -0.6053704185194108 -1.0447911817283915" rpy="0 0 0"/>
            <mass value="1" />
            <inertia ixx="100" ixy="0" ixz="0" iyy="100" iyz="0" izz="100" />
        </inertial>
        <visual>
            <origin xyz="-0.7851104569991724 -0.6053704185194108 -1.0447911817283915" rpy="0 0 0"/>
            <geometry>
                <box size="1.5702209139983447 1.2107408370388215 2.089582363456783" />
            </geometry>
            <material name="Cyan">
                <color rgba="0 1.0 1.0 1.0"/>
            </material>
        </visual>
        <collision>
            <origin xyz="-0.7851104569991724 -0.6053704185194108 -1.0447911817283915" rpy="0 0 0"/>
            <geometry>
                <box size="1.5702209139983447 1.2107408370388215 2.089582363456783" />
            </geometry>
        </collision>
    </link>
    <joint name="Body_Leg2" type="revolute">
       <parent link="Body"/>
       <child  link="Leg2"/>
       <origin rpy="0 0 0" xyz="1.6277722401816033 -1.371400352488661 3.4246521902900873" />
       <axis xyz="0 1 0"/>
       <limit effort="0.0" lower="-3.14159" upper="3.14159" velocity="0.0"/>
    </joint>
    <link name="Leg2">
        <inertial>
            <origin xyz="1.5387452925592853 -1.1771870722314621 -1.2828109869677908" rpy="0 0 0"/>
            <mass value="1" />
            <inertia ixx="100" ixy="0" ixz="0" iyy="100" iyz="0" izz="100" />
        </inertial>
        <visual>
            <origin xyz="1.5387452925592853 -1.1771870722314621 -1.2828109869677908" rpy="0 0 0"/>
            <geometry>
                <box size="3.0774905851185705 2.3543741444629243 2.5656219739355817" />
            </geometry>
            <material name="Cyan">
                <color rgba="0 1.0 1.0 1.0"/>
            </material>
        </visual>
        <collision>
            <origin xyz="1.5387452925592853 -1.1771870722314621 -1.2828109869677908" rpy="0 0 0"/>
            <geometry>
                <box size="3.0774905851185705 2.3543741444629243 2.5656219739355817" />
            </geometry>
        </collision>
    </link>
    <joint name="Body_Leg3" type="revolute">
       <parent link="Body"/>
       <child  link="Leg3"/>
       <origin rpy="0 0 0" xyz="1.6277722401816033 1.371400352488661 3.4246521902900873" />
       <axis xyz="0 1 0"/>
       <limit effort="0.0" lower="-3.14159" upper="3.14159" velocity="0.0"/>
    </joint>
    <link name="Leg3">
        <inertial>
            <origin xyz="2.102772639205241 1.5409248182294304 -1.1716327670463855" rpy="0 0 0"/>
            <mass value="1" />
            <inertia ixx="100" ixy="0" ixz="0" iyy="100" iyz="0" izz="100" />
        </inertial>
        <visual>
            <origin xyz="2.102772639205241 1.5409248182294304 -1.1716327670463855" rpy="0 0 0"/>
            <geometry>
                <box size="4.205545278410482 3.081849636458861 2.343265534092771" />
            </geometry>
            <material name="Cyan">
                <color rgba="0 1.0 1.0 1.0"/>
            </material>
        </visual>
        <collision>
            <origin xyz="2.102772639205241 1.5409248182294304 -1.1716327670463855" rpy="0 0 0"/>
            <geometry>
                <box size="4.205545278410482 3.081849636458861 2.343265534092771" />
            </geometry>
        </collision>
    </link>
    <joint name="Body_Leg4" type="revolute">
       <parent link="Body"/>
       <child  link="Leg4"/>
       <origin rpy="0 0 0" xyz="-1.6277722401816033 1.371400352488661 3.4246521902900873" />
       <axis xyz="0 1 0"/>
       <limit effort="0.0" lower="-3.14159" upper="3.14159" velocity="0.0"/>
    </joint>
    <link name="Leg4">
        <inertial>
            <origin xyz="-0.673854143626415 1.774821712577234 -1.7123260951450436" rpy="0 0 0"/>
            <mass value="1" />
            <inertia ixx="100" ixy="0" ixz="0" iyy="100" iyz="0" izz="100" />
        </inertial>
        <visual>
            <origin xyz="-0.673854143626415 1.774821712577234 -1.7123260951450436" rpy="0 0 0"/>
            <geometry>
                <box size="1.34770828725283 3.549643425154468 3.4246521902900873" />
            </geometry>
            <material name="Cyan">
                <color rgba="0 1.0 1.0 1.0"/>
            </material>
        </visual>
        <collision>
            <origin xyz="-0.673854143626415 1.774821712577234 -1.7123260951450436" rpy="0 0 0"/>
            <geometry>
                <box size="1.34770828725283 3.549643425154468 3.4246521902900873" />
            </geometry>
        </collision>
    </link>
</robot>